============================= test session starts ==============================
platform linux -- Python 3.9.2, pytest-7.1.2, pluggy-1.0.0
rootdir: /home/a2iediting/blastWeb
collected 1 item

tests/ncbiGW_test.py F                                                   [100%]

=================================== FAILURES ===================================
__________________________ TestNcbiData.test_ncbiData __________________________

self = <ncbiGW_test.TestNcbiData object at 0x7fba29f9c880>

    def test_ncbiData(self):
>       TestNcbiData.platypus.runGenomeWalk()

tests/ncbiGW_test.py:17: 
_ _ _ _ _ _ _ _ _ _ _ _ _ _ _ _ _ _ _ _ _ _ _ _ _ _ _ _ _ _ _ _ _ _ _ _ _ _ _ _ 
bin/ncbiData.py:68: in wrapper
    func(slf, *args, **kwargs)
_ _ _ _ _ _ _ _ _ _ _ _ _ _ _ _ _ _ _ _ _ _ _ _ _ _ _ _ _ _ _ _ _ _ _ _ _ _ _ _ 

self = <ncbiData.ncbiData object at 0x7fba29f4df40>

    @updateResources
    def runGenomeWalk(self) -> None:
        """Run genomeWalk.py for this object. Download input gtf and genome files if they are not downloaded yet. Then create process
        """
        if not "gtf" in self.fileDirectories:
            self.getResource("gtf")
        if not "dna" in self.fileDirectories:
            self.getResource("dna")
    
>       command = ["sudo", "-E", "python3", dConfig["scripts"]["multi_genome_walk_path"],
                           self.fileDirectories["dna"],
                           self.fileDirectories["gtfAnnotation"]]
E       NameError: name 'dConfig' is not defined

bin/ncbiData.py:194: NameError
=========================== short test summary info ============================
FAILED tests/ncbiGW_test.py::TestNcbiData::test_ncbiData - NameError: name 'd...
============================== 1 failed in 0.23s ===============================
============================= test session starts ==============================
platform linux -- Python 3.9.2, pytest-7.1.2, pluggy-1.0.0
rootdir: /home/a2iediting/blastWeb
collected 1 item

tests/ncbiGW_test.py F                                                   [100%]

=================================== FAILURES ===================================
__________________________ TestNcbiData.test_ncbiData __________________________

self = <ncbiGW_test.TestNcbiData object at 0x7f46125fc910>

    def test_ncbiData(self):
>       TestNcbiData.platypus.runGenomeWalk()

tests/ncbiGW_test.py:17: 
_ _ _ _ _ _ _ _ _ _ _ _ _ _ _ _ _ _ _ _ _ _ _ _ _ _ _ _ _ _ _ _ _ _ _ _ _ _ _ _ 
bin/ncbiData.py:68: in wrapper
    func(slf, *args, **kwargs)
_ _ _ _ _ _ _ _ _ _ _ _ _ _ _ _ _ _ _ _ _ _ _ _ _ _ _ _ _ _ _ _ _ _ _ _ _ _ _ _ 

self = <ncbiData.ncbiData object at 0x7f46125acfd0>

    @updateResources
    def runGenomeWalk(self) -> None:
        """Run genomeWalk.py for this object. Download input gtf and genome files if they are not downloaded yet. Then create process
        """
        if not "gtf" in self.fileDirectories:
            self.getResource("gtf")
        if not "dna" in self.fileDirectories:
            self.getResource("dna")
    
        command = ["sudo", "-E", "python3", dConfig["scripts"]["multi_genome_walk_path"],
                           self.fileDirectories["dna"],
>                          self.fileDirectories["gtfAnnotation"]]
E       KeyError: 'gtfAnnotation'

bin/ncbiData.py:196: KeyError
=========================== short test summary info ============================
FAILED tests/ncbiGW_test.py::TestNcbiData::test_ncbiData - KeyError: 'gtfAnno...
============================== 1 failed in 0.23s ===============================
